#VRML_SIM R2023b utf8

EXTERNPROTO "https://raw.githubusercontent.com/cyberbotics/webots/R2023b/projects/objects/trees/protos/BigSassafras.proto"
EXTERNPROTO "https://raw.githubusercontent.com/cyberbotics/webots/R2023b/projects/objects/trees/protos/Cypress.proto"
EXTERNPROTO "https://raw.githubusercontent.com/cyberbotics/webots/R2023b/projects/appearances/protos/DryMud.proto"
EXTERNPROTO "https://raw.githubusercontent.com/cyberbotics/webots/R2023b/projects/objects/trees/protos/Oak.proto"
EXTERNPROTO "https://raw.githubusercontent.com/cyberbotics/webots/R2023b/projects/objects/trees/protos/Pine.proto"
EXTERNPROTO "https://raw.githubusercontent.com/cyberbotics/webots/R2023b/projects/appearances/protos/Rubber.proto"
EXTERNPROTO "https://raw.githubusercontent.com/cyberbotics/webots/R2023b/projects/objects/trees/protos/SimpleTree.proto"
EXTERNPROTO "https://raw.githubusercontent.com/cyberbotics/webots/R2023b/projects/objects/backgrounds/protos/TexturedBackground.proto"
EXTERNPROTO "https://raw.githubusercontent.com/cyberbotics/webots/R2023b/projects/objects/backgrounds/protos/TexturedBackgroundLight.proto"
EXTERNPROTO "https://raw.githubusercontent.com/cyberbotics/webots/R2023b/projects/objects/floors/protos/UnevenTerrain.proto"
EXTERNPROTO "https://raw.githubusercontent.com/cyberbotics/webots/R2023b/projects/appearances/protos/ScuffedPlastic.proto"
EXTERNPROTO "https://raw.githubusercontent.com/cyberbotics/webots/R2023b/projects/appearances/protos/Pcb.proto"

WorldInfo {
}
Viewpoint {
  orientation 0.06096783814171552 -0.024497989960495084 -0.9978390507492784 3.9041963200351164
  position 91.32087167372015 -105.50522706849995 29.672723337501086
}
TexturedBackground {
}
TexturedBackgroundLight {
}
Robot {
  translation 3.7430239215856766 -6.313901240748682 3.791375033729831
  rotation 0.5433806382490535 -0.53348591122062 -0.6481745632969222 0.15528069103122566
  children [
    Solid {
      translation -0.58 4.58824e-07 0.34
      rotation 1 0 0 -1.5707953071795862
      children [
        Shape {
          appearance Pcb {
          }
          geometry Cylinder {
            height 3
            radius 0.05
          }
        }
      ]
      name "solid(4)"
    }
    Solid {
      translation 0.47 4.58824e-07 0.34
      rotation 1 0 0 -1.5707953071795862
      children [
        Shape {
          appearance Pcb {
          }
          geometry Cylinder {
            height 3
            radius 0.05
          }
        }
      ]
      name "solid(5)"
    }
    DEF base Shape {
      appearance ScuffedPlastic {
        colorOverride 0.333333 0.666667 0
      }
      geometry DEF Base Box {
        size 1.5 3.2 0.5
      }
    }
    DEF wheel1 HingeJoint {
      jointParameters HingeJointParameters {
        position -20.72778213160658
        anchor 0.75 -0.96 -0.53
      }
      device [
        RotationalMotor {
          name "wheel1"
          maxTorque 40
        }
      ]
      endPoint Solid {
        translation 0.7500056668700354 -0.9600047720329948 -0.5300598165887689
        rotation -0.6280237015777441 0.45952722859912587 -0.6280294232220298 2.2801019580814774
        children [
          DEF wheel Shape {
            appearance Rubber {
              type "dotted"
            }
            geometry Cylinder {
              height 0.5
              radius 0.5
              subdivision 50
            }
          }
        ]
        boundingObject USE wheel
        physics DEF phy1 Physics {
          mass 1
        }
        linearVelocity -9.332774211697683e-06 -9.758610523936611e-06 -1.3660168751804886e-06
        angularVelocity -6.134293568792056e-07 -3.3478331573778686e-07 4.9718099732570195e-06
      }
    }
    DEF wheel2 HingeJoint {
      jointParameters HingeJointParameters {
        position -45.16473043564949
        anchor -0.75 -0.96 -0.53
      }
      device [
        RotationalMotor {
          name "wheel2"
          maxTorque 40
        }
      ]
      endPoint Solid {
        translation -0.7500224218090552 -0.9599998147221469 -0.5298063909612896
        rotation -0.4868475408523023 0.7252025486099699 -0.48688883274898626 1.88662935947835
        children [
          DEF wheel Shape {
            appearance Rubber {
              type "dotted"
            }
            geometry Cylinder {
              height 0.5
              radius 0.5
              subdivision 50
            }
          }
        ]
        name "solid(1)"
        boundingObject USE wheel
        physics USE phy1
        linearVelocity -1.0067123102970692e-05 -1.7225210181271186e-05 -1.9591271107552712e-06
        angularVelocity -6.134068309086026e-07 -3.3467212098725473e-07 4.971820343249457e-06
      }
    }
    DEF wheel3 HingeJoint {
      jointParameters HingeJointParameters {
        position -30.519073078420668
        anchor 0.75 0.96 -0.53
      }
      device [
        RotationalMotor {
          name "wheel3"
          maxTorque 40
        }
      ]
      endPoint Solid {
        translation 0.7499912770032688 0.9600066486567704 -0.5299140124589311
        rotation 0.3977726970014251 0.8267744753283611 0.3977698435851134 1.7599059556725736
        children [
          DEF wheel Shape {
            appearance Rubber {
              type "dotted"
            }
            geometry Cylinder {
              height 0.5
              radius 0.5
              subdivision 50
            }
          }
        ]
        name "solid(2)"
        boundingObject USE wheel
        physics USE phy1
        linearVelocity -1.885323392653504e-05 -8.731134202039304e-06 -2.471408249050455e-06
        angularVelocity -6.134156452972965e-07 -3.3468424048744195e-07 4.971818675102597e-06
      }
    }
    DEF wheel4 HingeJoint {
      jointParameters HingeJointParameters {
        position -49.8588643971005
        anchor -0.75 0.96 -0.53
      }
      device [
        RotationalMotor {
          name "wheel4"
          maxTorque 40
        }
      ]
      endPoint Solid {
        translation -0.7499943566352494 0.9599952159395913 -0.53006228470976
        rotation 0.19791680288423913 0.9600299763679174 0.19791761824329188 1.611584968561582
        children [
          DEF wheel Shape {
            appearance Rubber {
              type "dotted"
            }
            geometry Cylinder {
              height 0.5
              radius 0.5
              subdivision 50
            }
          }
        ]
        name "solid(3)"
        boundingObject USE wheel
        physics USE phy1
        linearVelocity -1.9587498316446474e-05 -1.6197595764563246e-05 -3.064605092278754e-06
        angularVelocity -6.134143904868997e-07 -3.3468740144158923e-07 4.9718216006386925e-06
      }
    }
  ]
  boundingObject USE base
  physics USE phy1
  controller ""
  linearVelocity -1.4425824070514182e-05 -1.2883856821584772e-05 -2.204706707175319e-06
  angularVelocity -6.134156579984804e-07 -3.3468423657356766e-07 4.971818674359892e-06
}
DEF forest Solid {
  children [
    Pine {
      translation -15.62 20.85 1.15
      name "pine tree(6)"
    }
    Pine {
      translation -15.62 -10.45 1.15
      name "pine tree(5)"
    }
    Pine {
      translation 11.67 -10.45 1.45
      name "pine tree(3)"
    }
    Pine {
      translation 20.49 -10.45 2.81
      name "pine tree(4)"
    }
    Pine {
      translation 11.67 15.84 1.88
      name "pine tree(2)"
    }
    Pine {
      translation -4.35 9.25 2.22
      name "pine tree(1)"
    }
    Pine {
      translation -4.35 -3.53 2.18
    }
    SimpleTree {
      translation 0 0 3
    }
    SimpleTree {
      translation 6 0 3
      name "tree(1)"
    }
    SimpleTree {
      translation 6 10 3
      name "tree(2)"
    }
    SimpleTree {
      translation 16 15 3
      name "tree(3)"
    }
    SimpleTree {
      translation -16 -15 1.8
      name "tree(4)"
    }
    SimpleTree {
      translation 16 -15 3
      name "tree(5)"
    }
    SimpleTree {
      translation 5 -22 2
      name "tree(6)"
    }
    SimpleTree {
      translation -15 -22 2
      name "tree(7)"
    }
    SimpleTree {
      translation -9 22 2
      name "tree(8)"
    }
    SimpleTree {
      translation -18 16 2.5
      name "tree(9)"
    }
    SimpleTree {
      translation -22 -3 2
      name "tree(10)"
    }
    SimpleTree {
      translation 10 -8 3
      name "tree(11)"
    }
    SimpleTree {
      translation -5 -8 2.3
      name "tree(12)"
    }
    SimpleTree {
      translation 1 -17 2
      name "tree(13)"
    }
    Oak {
      translation 14.94 0 3.24
    }
    Oak {
      translation 20 -5.97 3.28
      name "oak tree(1)"
    }
    Oak {
      translation 15.97 -10.75 3.02
      name "oak tree(2)"
    }
    Oak {
      translation 15.97 11.04 3.07
      name "oak tree(3)"
    }
    Oak {
      translation -24.52 6.27 2.46
      name "oak tree(4)"
    }
    Oak {
      translation -12.06 2.39 2.09
      name "oak tree(6)"
    }
    Oak {
      translation -13.84 10.96 2.09
      name "oak tree(7)"
    }
    Oak {
      translation -2.97 18.97 1.79
      name "oak tree(8)"
    }
    Oak {
      translation 0.35 13.07 2.24
      name "oak tree(9)"
    }
    Oak {
      translation -9.22 15.64 2.72
      name "oak tree(5)"
    }
    Oak {
      translation 7.46 20.45 2.43
      name "oak tree(10)"
    }
    Oak {
      translation 16.74 21.4 2.43
      name "oak tree(11)"
    }
    BigSassafras {
      translation -11.82 -13.71 1.72
    }
    BigSassafras {
      translation -21.32 -8.95 1.72
      name "sassafras tree(1)"
    }
    BigSassafras {
      translation 19.67 7.95 3.44
      name "sassafras tree(2)"
    }
    BigSassafras {
      translation 19.67 -1.13 2.97
      name "sassafras tree(3)"
    }
    BigSassafras {
      translation 21.66 -19.93 2.97
      name "sassafras tree(4)"
    }
    BigSassafras {
      translation 9.84 -19.93 2.64
      name "sassafras tree(5)"
    }
    BigSassafras {
      translation -6.69 -19.93 1.29
      name "sassafras tree(6)"
    }
    BigSassafras {
      translation -16.82 -5.16 2.98
      name "sassafras tree(7)"
    }
    BigSassafras {
      translation -16.82 8.12 2.98
      name "sassafras tree(8)"
    }
    BigSassafras {
      translation -21.82 21.14 2.98
      name "sassafras tree(9)"
    }
    BigSassafras {
      translation 1.95 21.14 2.63
      name "sassafras tree(10)"
    }
    Cypress {
      translation -11.36 0 1.96
    }
    Cypress {
      translation -14.16 5.78 2.06
      name "cypress tree(1)"
    }
    Cypress {
      translation 20.42 15.8 3.01
      name "cypress tree(2)"
    }
    Cypress {
      translation 21.87 20.79 3.01
      name "cypress tree(3)"
    }
    Cypress {
      translation 11.51 1.81 3.01
      name "cypress tree(4)"
    }
    Cypress {
      translation 2.77 -10.75 2.51
      name "cypress tree(5)"
    }
    Cypress {
      translation -2.24 -21.57 1.87
      name "cypress tree(6)"
    }
    Cypress {
      translation 15.22 -21.57 2.5
      name "cypress tree(7)"
    }
    Cypress {
      translation 6.61 -15.53 2.8
      name "cypress tree(8)"
    }
    Cypress {
      translation -11.26 5.51 2.26
      name "cypress tree(9)"
    }
  ]
}
UnevenTerrain {
  appearance DryMud {
  }
}
DEF Border Solid {
  translation 0 0 3.9
  children [
    Solid {
      translation 0 -25.2 -0.37004705692665585
      children [
        DEF border Shape {
          appearance DryMud {
          }
          geometry Box {
            size 49 1 3
          }
        }
      ]
      name "border1"
      boundingObject USE border
      physics DEF phy1 Physics {
        mass 1
      }
      linearVelocity 0 0 -4.433786671143025e-15
    }
    Solid {
      translation 0 25.53 -0.37004705692665585
      children [
        DEF border Shape {
          appearance DryMud {
          }
          geometry Box {
            size 49 1 3
          }
        }
      ]
      name "border2"
      boundingObject USE border
      physics USE phy1
      linearVelocity 0 0 -4.433786671143025e-15
    }
    Solid {
      translation 25.53 0 -0.37
      rotation 0 0 1 1.5708
      children [
        DEF border Shape {
          appearance DryMud {
          }
          geometry Box {
            size 49 1 3
          }
        }
      ]
      name "border3"
      boundingObject USE border
    }
    Solid {
      translation -25.5301 1.57462e-05 -0.37004705692665585
      rotation 5.1580022398749126e-05 -9.550089548459884e-05 0.9999999941095401 1.569814080916819
      children [
        DEF border Shape {
          appearance DryMud {
          }
          geometry Box {
            size 49 1 3
          }
        }
      ]
      name "border4"
      boundingObject USE border
      physics USE phy1
      linearVelocity 0 0 -4.433786671143025e-15
    }
  ]
  name "solid(1)"
}
